
Pád workera
-----------
▶ Toto chování je "očekáváno"
    ◆ Systém jako celek se nezhroutí
      (ostatně komu záleží na nějaké výjimce :-)
  
16:59:03 default: worker.do_work() (c5468250-e2c5-494f-8bd8-f1f51b9a81f2)
Working
16:59:05 AssertionError
Traceback (most recent call last):
  File "/home/tester/.local/lib/python3.6/site-packages/rq/worker.py", line 793, in perform_job
    rv = job.perform()
  File "/home/tester/.local/lib/python3.6/site-packages/rq/job.py", line 599, in perform
    self._result = self._execute()
  File "/home/tester/.local/lib/python3.6/site-packages/rq/job.py", line 605, in _execute
    return self.func(*self.args, **self.kwargs)
  File "./worker.py", line 7, in do_work
    assert False
AssertionError
Traceback (most recent call last):
  File "/home/tester/.local/lib/python3.6/site-packages/rq/worker.py", line 793, in perform_job
    rv = job.perform()
  File "/home/tester/.local/lib/python3.6/site-packages/rq/job.py", line 599, in perform
    self._result = self._execute()
  File "/home/tester/.local/lib/python3.6/site-packages/rq/job.py", line 605, in _execute
    return self.func(*self.args, **self.kwargs)
  File "./worker.py", line 7, in do_work
    assert False
AssertionError
16:59:05 Moving job to 'failed' queue
